<mujoco model="gen3_robotiq_2f_85">
  <compiler angle="radian" meshdir="meshes/" autolimits="true"/>
  <statistic meansize="0.135667" extent="1.27963" center="6.60856e-06 -0.0231166 0.612477"/>
  <actuator>
    <!-- Physical limits of the actuator. Pulled directly from datasheet. See pg 24 of:
     https://www.kinovarobotics.com/sites/default/files/UG-014_KINOVA_Gen3_Ultra_lightweight_robot_User_guide_EN_R06_0.pdf -->
    <motor ctrllimited="true" ctrlrange="-39.0 39.0" joint="joint_1" name="torq_j1"/>
    <motor ctrllimited="true" ctrlrange="-39.0 39.0" joint="joint_2" name="torq_j2"/>
    <motor ctrllimited="true" ctrlrange="-39.0 39.0" joint="joint_3" name="torq_j3"/>
    <motor ctrllimited="true" ctrlrange="-39.0 39.0" joint="joint_4" name="torq_j4"/>
    <motor ctrllimited="true" ctrlrange="-9.0 9.0" joint="joint_5" name="torq_j5"/>
    <motor ctrllimited="true" ctrlrange="-9.0 9.0" joint="joint_6" name="torq_j6"/>
    <motor ctrllimited="true" ctrlrange="-9.0 9.0" joint="joint_7" name="torq_j7"/>
</actuator>
  <asset>
    <mesh name="base_link" file="base_link.STL"/>
    <mesh name="shoulder_link" file="shoulder_link.STL"/>
    <mesh name="half_arm_1_link" file="half_arm_1_link.STL"/>
    <mesh name="half_arm_2_link" file="half_arm_2_link.STL"/>
    <mesh name="forearm_link" file="forearm_link.STL"/>
    <mesh name="spherical_wrist_1_link" file="spherical_wrist_1_link.STL"/>
    <mesh name="spherical_wrist_2_link" file="spherical_wrist_2_link.STL"/>
    <mesh name="bracelet_with_vision_link" file="bracelet_with_vision_link.STL"/>
  </asset>
  <worldbody>
    <geom type="mesh" rgba="0.75294 0.75294 0.75294 1" mesh="base_link"/>
    <body name="shoulder_link" pos="0 0 0.15643" quat="-3.67321e-06 1 0 0">
      <inertial pos="-2.3e-05 -0.010364 -0.07336" quat="0.707051 0.0451246 -0.0453544 0.704263" mass="1.3773" diaginertia="0.00488868 0.00457 0.00135132"/>
      <joint name="joint_1" pos="0 0 0" axis="0 0 1"/>
      <geom type="mesh" rgba="0.75294 0.75294 0.75294 1" mesh="shoulder_link"/>
      <body name="half_arm_1_link" pos="0 0.005375 -0.12838" quat="0.707105 0.707108 0 0">
        <inertial pos="-4.4e-05 -0.09958 -0.013278" quat="0.482348 0.516286 -0.516862 0.483366" mass="1.1636" diaginertia="0.0113017 0.011088 0.00102532"/>
        <joint name="joint_2" pos="0 0 0" axis="0 0 1" range="-2.24 2.24"/>
        <geom type="mesh" rgba="0.75294 0.75294 0.75294 1" mesh="half_arm_1_link"/>
        <body name="half_arm_2_link" pos="0 -0.21038 -0.006375" quat="0.707105 -0.707108 0 0">
          <inertial pos="-4.4e-05 -0.006641 -0.117892" quat="0.706144 0.0213722 -0.0209128 0.707437" mass="1.1636" diaginertia="0.0111633 0.010932 0.00100671"/>
          <joint name="joint_3" pos="0 0 0" axis="0 0 1"/>
          <geom type="mesh" rgba="0.75294 0.75294 0.75294 1" mesh="half_arm_2_link"/>
          <body name="forearm_link" pos="0 0.006375 -0.21038" quat="0.707105 0.707108 0 0">
            <inertial pos="-1.8e-05 -0.075478 -0.015006" quat="0.483678 0.515961 -0.515859 0.483455" mass="0.9302" diaginertia="0.00834839 0.008147 0.000598606"/>
            <joint name="joint_4" pos="0 0 0" axis="0 0 1" range="-2.57 2.57"/>
            <geom type="mesh" rgba="0.75294 0.75294 0.75294 1" mesh="forearm_link"/>
            <body name="spherical_wrist_1_link" pos="0 -0.20843 -0.006375" quat="0.707105 -0.707108 0 0">
              <inertial pos="1e-06 -0.009432 -0.063883" quat="0.703558 0.0707492 -0.0707492 0.703558" mass="0.6781" diaginertia="0.00165901 0.001596 0.000346988"/>
              <joint name="joint_5" pos="0 0 0" axis="0 0 1"/>
              <geom type="mesh" rgba="0.75294 0.75294 0.75294 1" mesh="spherical_wrist_1_link"/>
              <body name="spherical_wrist_2_link" pos="0 0.00017505 -0.10593" quat="0.707105 0.707108 0 0">
                <inertial pos="1e-06 -0.045483 -0.00965" quat="0.44426 0.550121 -0.550121 0.44426" mass="0.6781" diaginertia="0.00170087 0.001641 0.00035013"/>
                <joint name="joint_6" pos="0 0 0" axis="0 0 1" range="-2.09 2.09"/>
                <geom type="mesh" rgba="0.75294 0.75294 0.75294 1" mesh="spherical_wrist_2_link"/>
                <body name="bracelet_link" pos="0 -0.10593 -0.00017505" quat="0.707105 -0.707108 0 0">
                  <inertial pos="0.000281 0.011402 -0.029798" quat="0.394358 0.596779 -0.577293 0.393789" mass="0.5" diaginertia="0.000657336 0.000587019 0.000320645"/>
                  <joint name="joint_7" pos="0 0 0" axis="0 0 1"/>
                  <geom type="mesh" rgba="0.75294 0.75294 0.75294 1" mesh="bracelet_with_vision_link"/>
                </body>
              </body>
            </body>
          </body>
        </body>
      </body>
    </body>
  </worldbody>
</mujoco>
